{"uuid": "a7b1ee8f-98be-4677-b9ab-7483e7508f01", "children": ["46505911-960f-4d3d-a60b-29b760a2415a"], "befores": [{"name": "run_app", "status": "broken", "statusDetails": {"message": "RuntimeError: No active exception to reraise\n", "trace": "  File \"C:\\Python37\\lib\\site-packages\\pluggy\\callers.py\", line 187, in _multicall\n    res = hook_impl.function(*args)\n  File \"C:\\Python37\\lib\\site-packages\\_pytest\\fixtures.py\", line 923, in pytest_fixture_setup\n    result = call_fixture_func(fixturefunc, request, kwargs)\n  File \"C:\\Python37\\lib\\site-packages\\_pytest\\fixtures.py\", line 779, in call_fixture_func\n    res = next(it)\n  File \"E:\\PycharmProjects\\app_automation_sh\\test_cases\\conftest.py\", line 47, in run_app\n  File \"E:\\PycharmProjects\\app_automation_sh\\test_cases\\conftest.py\", line 81, in _base_driver\n"}, "start": 1578669137839, "stop": 1578669137893}], "start": 1578669137839, "stop": 1578669137901}