{"uuid": "cd6b944c-1442-45b3-91ed-f2a11d1d46ea", "children": ["d1395a93-71b0-4c1a-b9d0-8e74d564e3e2"], "befores": [{"name": "run_app", "status": "broken", "statusDetails": {"message": "RuntimeError: No active exception to reraise\n", "trace": "  File \"C:\\Python37\\lib\\site-packages\\pluggy\\callers.py\", line 187, in _multicall\n    res = hook_impl.function(*args)\n  File \"C:\\Python37\\lib\\site-packages\\_pytest\\fixtures.py\", line 923, in pytest_fixture_setup\n    result = call_fixture_func(fixturefunc, request, kwargs)\n  File \"C:\\Python37\\lib\\site-packages\\_pytest\\fixtures.py\", line 779, in call_fixture_func\n    res = next(it)\n  File \"E:\\PycharmProjects\\app_automation_sh\\test_cases\\conftest.py\", line 47, in run_app\n  File \"E:\\PycharmProjects\\app_automation_sh\\test_cases\\conftest.py\", line 81, in _base_driver\n"}, "start": 1578669139351, "stop": 1578669139401}], "start": 1578669139351, "stop": 1578669139409}