{"uuid": "4b37f69e-6682-4169-99b3-110af4dd7577", "children": ["b9f54ce8-995f-44da-94ff-29a84177c02c"], "befores": [{"name": "run_app", "status": "broken", "statusDetails": {"message": "RuntimeError: No active exception to reraise\n", "trace": "  File \"C:\\Python37\\lib\\site-packages\\pluggy\\callers.py\", line 187, in _multicall\n    res = hook_impl.function(*args)\n  File \"C:\\Python37\\lib\\site-packages\\_pytest\\fixtures.py\", line 923, in pytest_fixture_setup\n    result = call_fixture_func(fixturefunc, request, kwargs)\n  File \"C:\\Python37\\lib\\site-packages\\_pytest\\fixtures.py\", line 779, in call_fixture_func\n    res = next(it)\n  File \"E:\\PycharmProjects\\app_automation_sh\\test_cases\\conftest.py\", line 47, in run_app\n  File \"E:\\PycharmProjects\\app_automation_sh\\test_cases\\conftest.py\", line 81, in _base_driver\n"}, "start": 1578669130899, "stop": 1578669130949}], "start": 1578669130899, "stop": 1578669130961}