{"uuid": "7be53b29-632d-47ad-8929-3a86929dfd86", "children": ["e6910109-f0ca-4159-b161-4021cae01f0f"], "befores": [{"name": "run_app", "status": "broken", "statusDetails": {"message": "RuntimeError: No active exception to reraise\n", "trace": "  File \"C:\\Python37\\lib\\site-packages\\pluggy\\callers.py\", line 187, in _multicall\n    res = hook_impl.function(*args)\n  File \"C:\\Python37\\lib\\site-packages\\_pytest\\fixtures.py\", line 923, in pytest_fixture_setup\n    result = call_fixture_func(fixturefunc, request, kwargs)\n  File \"C:\\Python37\\lib\\site-packages\\_pytest\\fixtures.py\", line 779, in call_fixture_func\n    res = next(it)\n  File \"E:\\PycharmProjects\\app_automation_sh\\test_cases\\conftest.py\", line 47, in run_app\n  File \"E:\\PycharmProjects\\app_automation_sh\\test_cases\\conftest.py\", line 81, in _base_driver\n"}, "start": 1578669134948, "stop": 1578669135033}], "start": 1578669134948, "stop": 1578669135047}