{"uuid": "8b5dc7d6-b231-4acf-9874-c76fa0f8e62f", "children": ["a2604efd-237b-45b9-a5ca-1ddf2f4bcefe"], "befores": [{"name": "run_app", "status": "broken", "statusDetails": {"message": "selenium.common.exceptions.WebDriverException: Message: An unknown server-side error occurred while processing the command. Original error: Could not find 'adb' in PATH. Please set the ANDROID_HOME or ANDROID_SDK_ROOT environment variables to the correct Android SDK root directory path.\n\n", "trace": "  File \"/Library/Frameworks/Python.framework/Versions/3.8/lib/python3.8/site-packages/pluggy/callers.py\", line 187, in _multicall\n    res = hook_impl.function(*args)\n  File \"/Library/Frameworks/Python.framework/Versions/3.8/lib/python3.8/site-packages/_pytest/fixtures.py\", line 957, in pytest_fixture_setup\n    result = call_fixture_func(fixturefunc, request, kwargs)\n  File \"/Library/Frameworks/Python.framework/Versions/3.8/lib/python3.8/site-packages/_pytest/fixtures.py\", line 783, in call_fixture_func\n    res = next(it)\n  File \"/Users/keen/PycharmProjects/app_automation_sh/test_cases/conftest.py\", line 47, in run_app\n    driver = _base_driver()\n  File \"/Users/keen/PycharmProjects/app_automation_sh/test_cases/conftest.py\", line 89, in _base_driver\n    driver = webdriver.Remote('http://127.0.0.1:{}/wd/hub'.format(server_port), desired_caps)\n  File \"/Library/Frameworks/Python.framework/Versions/3.8/lib/python3.8/site-packages/appium/webdriver/webdriver.py\", line 147, in __init__\n    super(WebDriver, self).__init__(\n  File \"/Library/Frameworks/Python.framework/Versions/3.8/lib/python3.8/site-packages/selenium/webdriver/remote/webdriver.py\", line 157, in __init__\n    self.start_session(capabilities, browser_profile)\n  File \"/Library/Frameworks/Python.framework/Versions/3.8/lib/python3.8/site-packages/appium/webdriver/webdriver.py\", line 227, in start_session\n    response = self.execute(RemoteCommand.NEW_SESSION, parameters)\n  File \"/Library/Frameworks/Python.framework/Versions/3.8/lib/python3.8/site-packages/selenium/webdriver/remote/webdriver.py\", line 321, in execute\n    self.error_handler.check_response(response)\n  File \"/Library/Frameworks/Python.framework/Versions/3.8/lib/python3.8/site-packages/selenium/webdriver/remote/errorhandler.py\", line 242, in check_response\n    raise exception_class(message, screen, stacktrace)\n"}, "start": 1578973633947, "stop": 1578973648906}], "start": 1578973633947, "stop": 1578973649226}