{"uuid": "e7427867-b63f-4c75-b1cd-fafa9d935d10", "children": ["41728c5e-d6d7-4170-98bf-81c78d9de79c"], "befores": [{"name": "run_app", "status": "broken", "statusDetails": {"message": "urllib3.exceptions.MaxRetryError: HTTPConnectionPool(host='127.0.0.1', port=4723): Max retries exceeded with url: /wd/hub/session (Caused by NewConnectionError('<urllib3.connection.HTTPConnection object at 0x00000000053F2240>: Failed to establish a new connection: [WinError 10061] 由于目标计算机积极拒绝，无法连接。'))\n", "trace": "  File \"C:\\Python37\\lib\\site-packages\\pluggy\\callers.py\", line 187, in _multicall\n    res = hook_impl.function(*args)\n  File \"C:\\Python37\\lib\\site-packages\\_pytest\\fixtures.py\", line 923, in pytest_fixture_setup\n    result = call_fixture_func(fixturefunc, request, kwargs)\n  File \"C:\\Python37\\lib\\site-packages\\_pytest\\fixtures.py\", line 779, in call_fixture_func\n    res = next(it)\n  File \"C:\\Users\\Administrator\\PycharmProjects\\app_automation_sh\\test_cases\\conftest.py\", line 47, in run_app\n    driver = _base_driver()\n  File \"C:\\Users\\Administrator\\PycharmProjects\\app_automation_sh\\test_cases\\conftest.py\", line 89, in _base_driver\n    driver = webdriver.Remote('http://127.0.0.1:{}/wd/hub'.format(server_port), desired_caps)\n  File \"C:\\Python37\\lib\\site-packages\\appium\\webdriver\\webdriver.py\", line 144, in __init__\n    proxy\n  File \"C:\\Python37\\lib\\site-packages\\selenium\\webdriver\\remote\\webdriver.py\", line 157, in __init__\n    self.start_session(capabilities, browser_profile)\n  File \"C:\\Python37\\lib\\site-packages\\appium\\webdriver\\webdriver.py\", line 219, in start_session\n    response = self.execute(RemoteCommand.NEW_SESSION, parameters)\n  File \"C:\\Python37\\lib\\site-packages\\selenium\\webdriver\\remote\\webdriver.py\", line 319, in execute\n    response = self.command_executor.execute(driver_command, params)\n  File \"C:\\Python37\\lib\\site-packages\\selenium\\webdriver\\remote\\remote_connection.py\", line 376, in execute\n    return self._request(command_info[0], url, body=data)\n  File \"C:\\Python37\\lib\\site-packages\\selenium\\webdriver\\remote\\remote_connection.py\", line 399, in _request\n    resp = self._conn.request(method, url, body=body, headers=headers)\n  File \"C:\\Python37\\lib\\site-packages\\urllib3\\request.py\", line 72, in request\n    **urlopen_kw)\n  File \"C:\\Python37\\lib\\site-packages\\urllib3\\request.py\", line 150, in request_encode_body\n    return self.urlopen(method, url, **extra_kw)\n  File \"C:\\Python37\\lib\\site-packages\\urllib3\\poolmanager.py\", line 324, in urlopen\n    response = conn.urlopen(method, u.request_uri, **kw)\n  File \"C:\\Python37\\lib\\site-packages\\urllib3\\connectionpool.py\", line 667, in urlopen\n    **response_kw)\n  File \"C:\\Python37\\lib\\site-packages\\urllib3\\connectionpool.py\", line 667, in urlopen\n    **response_kw)\n  File \"C:\\Python37\\lib\\site-packages\\urllib3\\connectionpool.py\", line 667, in urlopen\n    **response_kw)\n  File \"C:\\Python37\\lib\\site-packages\\urllib3\\connectionpool.py\", line 638, in urlopen\n    _stacktrace=sys.exc_info()[2])\n  File \"C:\\Python37\\lib\\site-packages\\urllib3\\util\\retry.py\", line 399, in increment\n    raise MaxRetryError(_pool, url, error or ResponseError(cause))\n"}, "start": 1578705178115, "stop": 1578705183301}], "start": 1578705178115, "stop": 1578705183546}