{"uuid": "50efeeb1-7314-4ffd-8981-382d6ed4293b", "children": ["a8353a62-2a70-47e5-a5e6-29d9f9ae1156"], "befores": [{"name": "run_app", "status": "broken", "statusDetails": {"message": "RuntimeError: No active exception to reraise\n", "trace": "  File \"C:\\Python37\\lib\\site-packages\\pluggy\\callers.py\", line 187, in _multicall\n    res = hook_impl.function(*args)\n  File \"C:\\Python37\\lib\\site-packages\\_pytest\\fixtures.py\", line 923, in pytest_fixture_setup\n    result = call_fixture_func(fixturefunc, request, kwargs)\n  File \"C:\\Python37\\lib\\site-packages\\_pytest\\fixtures.py\", line 779, in call_fixture_func\n    res = next(it)\n  File \"E:\\PycharmProjects\\app_automation_sh\\test_cases\\conftest.py\", line 47, in run_app\n  File \"E:\\PycharmProjects\\app_automation_sh\\test_cases\\conftest.py\", line 81, in _base_driver\n"}, "start": 1578669136024, "stop": 1578669136075}], "start": 1578669136024, "stop": 1578669136083}