ERROR    root:basepage.py:36 等待元素 ('id', 'com.cashier.jiutongshanghu:id/ed_login_phone') 可见 失败！
Traceback (most recent call last):
  File "/Users/keen/PycharmProjects/app_automation_sh/common/basepage.py", line 33, in wait_ele_visible
    WebDriverWait(self.driver, timeout, frequency).until(ec.visibility_of_element_located(loc))
  File "/Library/Frameworks/Python.framework/Versions/3.8/lib/python3.8/site-packages/selenium/webdriver/support/wait.py", line 71, in until
    value = method(self._driver)
  File "/Library/Frameworks/Python.framework/Versions/3.8/lib/python3.8/site-packages/selenium/webdriver/support/expected_conditions.py", line 128, in __call__
    return _element_if_visible(_find_element(driver, self.locator))
  File "/Library/Frameworks/Python.framework/Versions/3.8/lib/python3.8/site-packages/selenium/webdriver/support/expected_conditions.py", line 415, in _find_element
    raise e
  File "/Library/Frameworks/Python.framework/Versions/3.8/lib/python3.8/site-packages/selenium/webdriver/support/expected_conditions.py", line 411, in _find_element
    return driver.find_element(*by)
  File "/Library/Frameworks/Python.framework/Versions/3.8/lib/python3.8/site-packages/appium/webdriver/webdriver.py", line 282, in find_element
    return self.execute(RemoteCommand.FIND_ELEMENT, {
  File "/Library/Frameworks/Python.framework/Versions/3.8/lib/python3.8/site-packages/selenium/webdriver/remote/webdriver.py", line 321, in execute
    self.error_handler.check_response(response)
  File "/Library/Frameworks/Python.framework/Versions/3.8/lib/python3.8/site-packages/appium/webdriver/errorhandler.py", line 29, in check_response
    raise wde
  File "/Library/Frameworks/Python.framework/Versions/3.8/lib/python3.8/site-packages/appium/webdriver/errorhandler.py", line 24, in check_response
    super(MobileErrorHandler, self).check_response(response)
  File "/Library/Frameworks/Python.framework/Versions/3.8/lib/python3.8/site-packages/selenium/webdriver/remote/errorhandler.py", line 242, in check_response
    raise exception_class(message, screen, stacktrace)
selenium.common.exceptions.WebDriverException: Message: An unknown server-side error occurred while processing the command. Original error: Could not proxy command to remote server. Original error: Error: socket hang up

ERROR    root:basepage.py:200 网页截图失败！
Traceback (most recent call last):
  File "/Users/keen/PycharmProjects/app_automation_sh/common/basepage.py", line 33, in wait_ele_visible
    WebDriverWait(self.driver, timeout, frequency).until(ec.visibility_of_element_located(loc))
  File "/Library/Frameworks/Python.framework/Versions/3.8/lib/python3.8/site-packages/selenium/webdriver/support/wait.py", line 71, in until
    value = method(self._driver)
  File "/Library/Frameworks/Python.framework/Versions/3.8/lib/python3.8/site-packages/selenium/webdriver/support/expected_conditions.py", line 128, in __call__
    return _element_if_visible(_find_element(driver, self.locator))
  File "/Library/Frameworks/Python.framework/Versions/3.8/lib/python3.8/site-packages/selenium/webdriver/support/expected_conditions.py", line 415, in _find_element
    raise e
  File "/Library/Frameworks/Python.framework/Versions/3.8/lib/python3.8/site-packages/selenium/webdriver/support/expected_conditions.py", line 411, in _find_element
    return driver.find_element(*by)
  File "/Library/Frameworks/Python.framework/Versions/3.8/lib/python3.8/site-packages/appium/webdriver/webdriver.py", line 282, in find_element
    return self.execute(RemoteCommand.FIND_ELEMENT, {
  File "/Library/Frameworks/Python.framework/Versions/3.8/lib/python3.8/site-packages/selenium/webdriver/remote/webdriver.py", line 321, in execute
    self.error_handler.check_response(response)
  File "/Library/Frameworks/Python.framework/Versions/3.8/lib/python3.8/site-packages/appium/webdriver/errorhandler.py", line 29, in check_response
    raise wde
  File "/Library/Frameworks/Python.framework/Versions/3.8/lib/python3.8/site-packages/appium/webdriver/errorhandler.py", line 24, in check_response
    super(MobileErrorHandler, self).check_response(response)
  File "/Library/Frameworks/Python.framework/Versions/3.8/lib/python3.8/site-packages/selenium/webdriver/remote/errorhandler.py", line 242, in check_response
    raise exception_class(message, screen, stacktrace)
selenium.common.exceptions.WebDriverException: Message: An unknown server-side error occurred while processing the command. Original error: Could not proxy command to remote server. Original error: Error: socket hang up


During handling of the above exception, another exception occurred:

Traceback (most recent call last):
  File "/Users/keen/PycharmProjects/app_automation_sh/common/basepage.py", line 198, in save_img
    self.driver.save_screenshot(img_path)
  File "/Library/Frameworks/Python.framework/Versions/3.8/lib/python3.8/site-packages/selenium/webdriver/remote/webdriver.py", line 1055, in save_screenshot
    return self.get_screenshot_as_file(filename)
  File "/Library/Frameworks/Python.framework/Versions/3.8/lib/python3.8/site-packages/selenium/webdriver/remote/webdriver.py", line 1032, in get_screenshot_as_file
    png = self.get_screenshot_as_png()
  File "/Library/Frameworks/Python.framework/Versions/3.8/lib/python3.8/site-packages/selenium/webdriver/remote/webdriver.py", line 1064, in get_screenshot_as_png
    return base64.b64decode(self.get_screenshot_as_base64().encode('ascii'))
  File "/Library/Frameworks/Python.framework/Versions/3.8/lib/python3.8/site-packages/selenium/webdriver/remote/webdriver.py", line 1074, in get_screenshot_as_base64
    return self.execute(Command.SCREENSHOT)['value']
  File "/Library/Frameworks/Python.framework/Versions/3.8/lib/python3.8/site-packages/selenium/webdriver/remote/webdriver.py", line 321, in execute
    self.error_handler.check_response(response)
  File "/Library/Frameworks/Python.framework/Versions/3.8/lib/python3.8/site-packages/appium/webdriver/errorhandler.py", line 29, in check_response
    raise wde
  File "/Library/Frameworks/Python.framework/Versions/3.8/lib/python3.8/site-packages/appium/webdriver/errorhandler.py", line 24, in check_response
    super(MobileErrorHandler, self).check_response(response)
  File "/Library/Frameworks/Python.framework/Versions/3.8/lib/python3.8/site-packages/selenium/webdriver/remote/errorhandler.py", line 242, in check_response
    raise exception_class(message, screen, stacktrace)
selenium.common.exceptions.WebDriverException: Message: An unknown server-side error occurred while processing the command. Original error: Could not proxy command to remote server. Original error: Error: socket hang up